<?xml version="1.0" encoding="UTF-8"?>
<testng-results ignored="1" total="3" passed="1" failed="1" skipped="0">
  <reporter-output>
  </reporter-output>
  <suite started-at="2024-01-14T17:04:04Z" name="Suite" finished-at="2024-01-14T17:04:08Z" duration-ms="3726">
    <groups>
    </groups>
    <test started-at="2024-01-14T17:04:04Z" name="Test" finished-at="2024-01-14T17:04:08Z" duration-ms="3726">
      <class name="apitest.GetUsers">
        <test-method is-config="true" signature="setUp()[pri:0, instance:apitest.GetUsers@ac20bb4]" started-at="2024-01-14T17:04:04Z" name="setUp" finished-at="2024-01-14T17:04:05Z" duration-ms="951" status="PASS">
          <reporter-output>
          </reporter-output>
        </test-method> <!-- setUp -->
        <test-method signature="getSingleUserNotFound()[pri:1, instance:apitest.GetUsers@ac20bb4]" started-at="2024-01-14T17:04:05Z" name="getSingleUserNotFound" description="To get the details of user with id 3" finished-at="2024-01-14T17:04:07Z" duration-ms="2242" status="PASS">
          <reporter-output>
          </reporter-output>
        </test-method> <!-- getSingleUserNotFound -->
        <test-method signature="getUsers()[pri:2, instance:apitest.GetUsers@ac20bb4]" started-at="2024-01-14T17:04:07Z" name="getUsers" description="To create a new user" finished-at="2024-01-14T17:04:08Z" duration-ms="361" status="FAIL">
          <exception class="java.lang.AssertionError">
            <message>
              <![CDATA[expected [202] but found [200]]]>
            </message>
            <full-stacktrace>
              <![CDATA[java.lang.AssertionError: expected [202] but found [200]
at org.testng.Assert.fail(Assert.java:96)
at org.testng.Assert.failNotEquals(Assert.java:776)
at org.testng.Assert.assertEqualsImpl(Assert.java:137)
at org.testng.Assert.assertEquals(Assert.java:118)
at org.testng.Assert.assertEquals(Assert.java:652)
at org.testng.Assert.assertEquals(Assert.java:662)
at apitest.GetUsers.getUsers(GetUsers.java:60)
at java.base/jdk.internal.reflect.NativeMethodAccessorImpl.invoke0(Native Method)
at java.base/jdk.internal.reflect.NativeMethodAccessorImpl.invoke(NativeMethodAccessorImpl.java:77)
at java.base/jdk.internal.reflect.DelegatingMethodAccessorImpl.invoke(DelegatingMethodAccessorImpl.java:43)
at java.base/java.lang.reflect.Method.invoke(Method.java:568)
at org.testng.internal.MethodInvocationHelper.invokeMethod(MethodInvocationHelper.java:124)
at org.testng.internal.Invoker.invokeMethod(Invoker.java:583)
at org.testng.internal.Invoker.invokeTestMethod(Invoker.java:719)
at org.testng.internal.Invoker.invokeTestMethods(Invoker.java:989)
at org.testng.internal.TestMethodWorker.invokeTestMethods(TestMethodWorker.java:125)
at org.testng.internal.TestMethodWorker.run(TestMethodWorker.java:109)
at org.testng.TestRunner.privateRun(TestRunner.java:648)
at org.testng.TestRunner.run(TestRunner.java:505)
at org.testng.SuiteRunner.runTest(SuiteRunner.java:455)
at org.testng.SuiteRunner.runSequentially(SuiteRunner.java:450)
at org.testng.SuiteRunner.privateRun(SuiteRunner.java:415)
at org.testng.SuiteRunner.run(SuiteRunner.java:364)
at org.testng.SuiteRunnerWorker.runSuite(SuiteRunnerWorker.java:52)
at org.testng.SuiteRunnerWorker.run(SuiteRunnerWorker.java:84)
at org.testng.TestNG.runSuitesSequentially(TestNG.java:1208)
at org.testng.TestNG.runSuitesLocally(TestNG.java:1137)
at org.testng.TestNG.runSuites(TestNG.java:1049)
at org.testng.TestNG.run(TestNG.java:1017)
at org.testng.remote.AbstractRemoteTestNG.run(AbstractRemoteTestNG.java:115)
at org.testng.remote.RemoteTestNG.initAndRun(RemoteTestNG.java:251)
at org.testng.remote.RemoteTestNG.main(RemoteTestNG.java:77)
]]>
            </full-stacktrace>
          </exception> <!-- java.lang.AssertionError -->
          <reporter-output>
          </reporter-output>
        </test-method> <!-- getUsers -->
      </class> <!-- apitest.GetUsers -->
    </test> <!-- Test -->
  </suite> <!-- Suite -->
</testng-results>
